Workbook

Sheet LIST CUSTOMER
A1: LIST CUST NOV 2021
A2: No. | B2: Cust | C2: BL Number | D2: SHIPMENT | E2: PELAYARAN | F2: Cont/Package | G2: Qty | H2: SO No. | I2: No. AJU | J2: POL/POD | K2: LOKASI TIMBUN | L2: ETD | M2: ETA | N2: SPPB | O2: KIRIM CARGO | P2: BONGKAR | Q2: MOBIL | R2: KIRIM INV | S2: JO NO | T2: PAYMENT INV | U2: PROFIT | V2: REFUND CUST | W2: REK | X2: TRANSFER DATE
A3: IMPORT
A4: 1 | B4: PT. TOPCO TRADING INDONESIA | C4: YHJKT-046-016-21JP | D4: IMPORT | E4: NTL NAIGAI / CC | F4: 2.604CBM | G4: LCL | H4: 079/QUO-MCL/11-2021 | I4: 001303 | J4: YOKOHAMA | K4: AIRIN | L4: 14/10/2021 | M4: 44266 | N4: 44297 | O4: 44327 | P4: 44327 | Q4: DMV | R4: 29/11/2021 | S4: 101222 | T4: 24/12/2021 | U4: 1321000 | V4: 150000 | W4: BCA 0830129774 A/N FELIPE FANGIO CHUNG | X4: -
A5: 2 | B5: PT. TOPCO TRADING INDONESIA | C5: YHJKT-046-003-21JP | D5: IMPORT | E5: NTL NAIGAI / CC | F5: 0.940CBM | G5: LCL | H5: 002/QUO-MCL/11-2021 | I5: 001302 | J5: YOKOHAMA | K5: AIRIN | L5: 14/10/2021 | M5: 44266 | N5: 44297 | O5: 44327 | P5: 44327 | Q5: DMV | R5: 29/11/2021 | S5: 101211 | U5: 1950000 | V5: 150000
A6: 3 | B6: PT. POLYCHEMIE ASIA PACIFIC PERMAI | C6: SNKO010210907345 | D6: IMPORT | E6: SINOKOR / CC | F6: TCKU1593513, TEMU5861481 & HALU2052431 | G6: 3X20GP | H6: 012/QUO-VJL/11-2021 | I6: 000214 | J6: BUSAN | K6: UTC1 | L6: 23/10/2021 | M6: 44480 | N6: 44480 | O6: 44480 | P6: 44511 | Q6: PTP | R6: 25/11/2021 | S6: VJL21110050 101301 | T6: - | U6: 919000 | V6: 50000 | W6: CIMB 705899545600 A/N RONALD TOBING | X6: 44867
V7: 150000 | W7: BCA 5390525798 A/N ASIAH | X7: 44867
A8: 4 | B8: PT. POLYCHEMIE ASIA PACIFIC PERMAI | C8: HASLC01211001803 | D8: IMPORT | E8: HASPUL / CC | F8: GLDU9759745 & FCIU6060497 | G8: 2X20GP | H8: 013/QUO-VJL/11-2021 | I8: 000222 | J8: SHANGHAI | K8: UTC1 | L8: 44297 | M8: 44511 | N8: 44511 | O8: 44511 | P8: 44541 | Q8: PTP | R8: 44511 | S8: VJL21110052 101496(0450/INV-VJL/12-21) - 100395 | T8: - | U8: 475000 | V8: 50000 | W8: CIMB 705899545600 A/N RONALD TOBING | X8: -
V9: 100000 | W9: BCA 5390525798 A/N ASIAH | X9: -
A10: 5 | B10: PT. POLYCHEMIE ASIA PACIFIC PERMAI | C10: XBJD031400 | D10: IMPORT | E10: CNC / CC | F10: SEGU2000919 | G10: 1X20GP | H10: 014/QUO-VJL/11-2021 | I10: 000224 | J10: NINGBO | K10: UTC1 | L10: 44358 | M10: 13/11/2021 | N10: 15/11/2021 | O10: 15/11/2021 | P10: 16/11/2021 | Q10: MJT | R10: 26/11/2021 | S10: 10063 | T10: - | U10: 339000 | V10: 50000 | W10: CIMB 705899545600 A/N RONALD TOBING | X10: 44867
V11: 50000 | W11: BCA 5390525798 A/N ASIAH | X11: 44867
A12: 6 | B12: PT. POLYCHEMIE ASIA PACIFIC PERMAI | C12: HASLC01211100442 | D12: IMPORT | E12: HASPUL / CC | F12: BSIU3036391 | G12: 1X20GP | H12: 033/QUO-VJL/11-2021 | I12: 000225 | J12: SHANGHAI | K12: UTC1 | L12: 13/11/2021 | M12: 21/11/2021 | N12: 22/11/2021 | O12: 23/11/2021 | P12: 24/11/2021 | Q12: PTP | R12: 22/11/2021 | S12: VJL21110114 101303 | T12: - | U12: 387000 | V12: - | W12: CIMB 705899545600 A/N RONALD TOBING | X12: -
V13: - | W13: BCA 5390525798 A/N ASIAH | X13: -
A14: 7 | B14: PT. POLYCHEMIE ASIA PACIFIC PERMAI | C14: IRSINJKT2122705 | D14: IMPORT | E14: GANINDO / CC | F14: RFCU2021693 | G14: 1X20GP | H14: 051/QUO-VJL/11-2021 | I14: 000233 | J14: SINGAPORE | K14: UTC1 | L14: 22/11/2021 | M14: 24/11/2021 | N14: 25/11/2021 | O14: 25/11/2021 | P14: 26/11/2021 | Q14: MJT | R14: 23/11/2021 | S14: VJL21110127 101495 | T14: - | U14: 693050 | V14: 50000 | W14: CIMB 705899545600 A/N RONALD TOBING | X14: -
V15: 50000 | W15: BCA 5390525798 A/N ASIAH | X15: -
A16: 8 | B16: PT. POLYCHEMIE ASIA PACIFIC PERMAI | C16: HASLC01211005717 | D16: IMPORT | E16: HASPUL / CC | F16: BEAU2408236 & TCKU1762357 | G16: 2X20GP | H16: 034/QUO-VJL/11-2021 | I16: 000225 | J16: SHANGHAI | K16: KOJA | L16: 14/11/2021 | M16: 26/11/2021 | N16: 26/11/2021 | O16: 26/11/2021 | P16: 27/11/2021 | Q16: PMP | R16: 25/11/2021 | S16: VJL21110148 101198 | T16: - | U16: 579000 | V16: 50000 | W16: CIMB 705899545600 A/N RONALD TOBING | X16: -
V17: 100000 | W17: BCA 5390525798 A/N ASIAH | X17: -
A18: 9 | B18: PT. POLYOSHIKA | C18: COAU7234585500 | D18: IMPORT | E18: COSCO / CC | F18: CSNU1576346 & CSLU1126188 | G18: 2X20GP | H18: 052/QUO-VJL/11-2021 | I18: 000052 | J18: PASIR GUDANG | K18: UTC1 | L18: 19/11/2021 | M18: 26/11/2021 | N18: 26/11/2021 | O18: 27/11/2021 | P18: 28/11/2021 | Q18: MJT | R18: 25/11/2021 | S18: VJL21110149 101300 | T18: PAID | U18: 581000 | V18: 50000 | W18: CIMB 705899545600 A/N RONALD TOBING | X18: 31/12/2021
V19: 100000 | W19: BCA 5390525798 A/N ASIAH
A20: 10 | B20: PT. POLYCHEMIE ASIA PACIFIC PERMAI | C20: COAU7234686140 | D20: IMPORT | E20: COSCO / CC | F20: BMOU2718540 | G20: 1X20GP | H20: 053/QUO-VJL/11-2021 | I20: 000234 | J20: PASIR GUDANG | K20: UTC1 | L20: 19/11/2021 | M20: 26/11/2021 | N20: 26/11/2021 | O20: 27/11/2021 | P20: 28/11/2021 | Q20: PMP | R20: 29/11/2021 | S20: VJL21110165 101216 | T20: - | U20: 379000 | V20: 50000 | W20: CIMB 705899545600 A/N RONALD TOBING | X20: -
V21: 50000 | W21: BCA 5390525798 A/N ASIAH | X21: -
A22: 11 | B22: PT. POLYCHEMIE ASIA PACIFIC PERMAI | C22: SITGNBJT865988 | D22: IMPORT | E22: SITC / CC | F22: SEGU3465037 | G22: 1X20GP | H22: 059/QUO-VJL/11-2021 | I22: 000235 | J22: NINGBO | K22: UTC1 | L22: 20/11/2021 | M22: 30/11/2021 | N22: 44208 | O22: 44239 | P22: 44239 | Q22: PMP | R22: 29/11/2021 | S22: VJL21110165 101216 | T22: - | U22: 255000 | V22: 50000 | W22: CIMB 705899545600 A/N RONALD TOBING | X22: -
V23: 50000 | W23: BCA 5390525798 A/N ASIAH | X23: -
A24: EXPORT
A25: 12 | B25: PT. KALOSO ARTHA INFINITY | C25: JKT21-00012/ANR | D25: EXPORT | E25: SCL | F25: 5.185 CBM | G25: LCL | H25: 028/QUO-VJL/11-2021 | I25: - | J25: ANTWERP | K25: - | L25: - | M25: - | N25: - | O25: - | P25: - | Q25: - | R25: 17/11/2021 | S25: VJL21110090 101175 | T25: - | U25: 1710125 | V25: - | W25: - | X25: -
A26: 13 | B26: PT. TETUKO ANUGERAH NUSANTARA | C26: JKT21-00016/BKK | D26: EXPORT | E26: FM GLOBAL | F26: 12.672CBM | G26: LCL | H26: 017/QUO-VJL/11-2021 | I26: - | J26: BANGKOK | K26: APW | L26: 25/11/2021 | M26: 44328 | N26: - | O26: - | P26: - | Q26: TAN | R26: 26/11/2021 | S26: 101227 | T26: 30/11/2021 | U26: 2650043 | V26: 5372928 | W26: BCA 6240441533 A/N UMIYATI | X26: 44267
A27: 14 | B27: PT. POLYCHEMIE ASIA PACIFIC PERMAI | C27: JKT21-00027/PKG | D27: EXPORT | E27: SCL | F27: 2.470CBM | G27: LCL | H27: 015/QUO-VJL/11-2021 | I27: - | J27: PORTKLANG | K27: DMV | L27: 27/11/2021 | M27: 44239 | N27: - | O27: STUF: 25/11/2021 | P27: - | Q27: GAFA | R27: 44359 | S27: 101264 | T27: - | U27: 2339850 | V27: 172900 | W27: CIMB 705899545600 A/N RONALD TOBING | X27: 44867
V28: 500000 | W28: BCA 5390525798 A/N ASIAH | X28: 44867
A29: 15 | B29: PT. GARUDAFOOD PUTRA PUTRI JAYA TBK | C29: ONEYSUBB95625800 | D29: EXPORT | E29: MACOLINE SBY | F29: ONEU0138486 & KKFU8156765 | G29: 2X40HQ | H29: 018/QUO-VJL/11-2021 | I29: - | J29: YANGON | K29: SBY | L29: 28/11/2021 | M29: 14/12/2021 | N29: - | O29: STUF: 24/11/2021 | P29: - | Q29: GARUDA | R29: 44481 | S29: 101266 | T29: - | U29: 7585590 | V29: 750000 | W29: BCA 5390525798 A/N ASIAH | X29: -
T30: Total Profit | U30: =SUM(U4:U29) -> 22163658 | V30: =V7+V9+V11+V29+V17+V15+V19+V21+V28 -> 1850000 | W30: ASIAH
T31: Komisi Ika | U31: =U30*10/100 -> 2216365.8
A34: LIST CUST DES 2021
A35: No. | B35: Cust | C35: BL Number | D35: SHIPMENT | E35: PELAYARAN | F35: Cont/Package | G35: Qty | H35: Quot No. | I35: No. AJU | J35: POL/POD | K35: LOKASI TIMBUN | L35: ETD | M35: ETA | N35: SPPB | O35: KIRIM CARGO | P35: BONGKAR | Q35: MOBIL | R35: KIRIM INV | S35: JO NO | T35: PAYMENT INV | U35: PROFIT | V35: REFUND CUST | W35: REK | X35: TRANSFER DATE
A36: IMPORT
A37: 1 | B37: PT. POLYCHEMIE ASIA PACIFIC PERMAI | C37: SITTADJT037174 | D37: IMPORT | E37: SITC / CC | F37: SITU2816120 | G37: 1X20GP | H37: 051/QUO-VJL/12-2021 | I37: 000252 | J37: QINGDAO | K37: UTC1 | L37: 15/12/2021 | M37: 22/12/2021 | N37: 23/12/2021 | O37: 23/12 REPO KIRIM 26/12 | P37: 27/12/2021 | Q37: PMP / REPO | R37: 17/12/2021 | S37: VJL21120114 101353 | T37: - | U37: 1374500 | V37: 50000 | W37: CIMB 705899545600 A/N RONALD TOBING | X37: -
V38: 50000 | W38: BCA 5390525798 A/N ASIAH | X38: -
A39: 2 | B39: PT. POLYCHEMIE ASIA PACIFIC PERMAI | C39: OOLU4110288780 | D39: IMPORT | E39: OOCL / CC | F39: OOLU0412330 | G39: 1X20GP | H39: 036/QUO-VJL/11-2021 | I39: 000231 | J39: OSAKA | K39: KOJA | L39: 13/11/2021 | M39: 44208 | N39: 44208 | O39: 44239 | P39: 44267 | Q39: PMP | R39: 29/12/2021 | S39: VJL21110176 101217 | T39: - | U39: 339000 | V39: 50000 | W39: CIMB 705899545600 A/N RONALD TOBING | X39: -
V40: 50000 | W40: BCA 5390525798 A/N ASIAH | X40: -
A41: 3 | B41: PT. POLYOSHIKA | C41: EGLV020100582260 | D41: IMPORT | E41: EVERGREEN / CC | F41: DRYU2574593 | G41: 1X20GP | H41: 058/QUO-VJL/11-2021 | I41: 000051 | J41: OSAKA | K41: NPCT1 | L41: 44511 | M41: 44208 | N41: 44208 | O41: 44239 | P41: 44239 | Q41: PMP | R41: 29/12/2021 | S41: VJL21110177 101226 | T41: - | U41: 419000 | V41: 50000 | W41: CIMB 705899545600 A/N RONALD TOBING | X41: -
V42: 50000 | W42: BCA 5390525798 A/N ASIAH | X42: -
...

Sheet CICILAN EMAS 10GR
A1: ANGSURAN EMAS 10GR - 3THN (36 BULAN)
A4: No. | B4: Angsuran ke | C4: Jth Tempo | D4: Nominal | E4: Paid Tgl | F4: Keterangan
A5: 1 | B5: DP/UM | C5: 44585 | D5: 1394100 | E5: 44585 | F5: UPS
A6: 2 | B6: Admin | C6: 44585 | D6: 50000 | E6: 44585 | F6: UPS
A7: 3 | B7: 1 | C7: 44616 | D7: 303547 | E7: 44609 | F7: VIA MANDIRI + 2,5K ADM
A8: 4 | B8: 2 | C8: 44644 | D8: 303547 | E8: 44628 | F8: VIA MANDIRI + 2,5K ADM
A9: 5 | B9: 3 | C9: 44675 | D9: 303547 | E9: 44653 | F9: VIA MANDIRI + 2,5K ADM
A10: 6 | B10: 4 | C10: 44705 | D10: 303547 | E10: 44685 | F10: VIA MANDIRI + 2,5K ADM
A11: 7 | B11: 5 | C11: 44736 | D11: 303547 | E11: 44723 | F11: VIA MANDIRI + 2,5K ADM
A12: 8 | B12: 6 | C12: 44766 | D12: 303547 | E12: 44746 | F12: VIA MANDIRI + 2,5K ADM
A13: 9 | B13: 7 | C13: 44797 | D13: 303547 | E13: 44774 | F13: VIA BCA + 2,5K ADM
A14: 10 | B14: 8 | C14: 44828 | D14: 303547 | E14: 44810 | F14: VIA BCA + 2,5K ADM
A15: 11 | B15: 9 | C15: 44858 | D15: 303547 | E15: 44846 | F15: VIA BCA + 2,5K ADM
A16: 12 | B16: 10 | C16: 44889 | D16: 303547 | E16: 44886 | F16: VIA BCA + 2,5K ADM
A17: 13 | B17: 11 | C17: 44919 | D17: 303547 | E17: 44900 | F17: VIA BCA + 2,5K ADM
A18: 14 | B18: 12 | C18: 44950 | D18: 303547 | E18: 44933 | F18: VIA BCA + 2,5K ADM
... A25: 21 | B25: 19 | C25: 45162 | D25: 303547 | E25: 45140 | F25: VIA BCA + 2,5K ADM
A26: 22 | B26: 20 | C26: 45193 | D26: 303547 | F26: VIA BCA + 2,5K ADM
A27: 23 | B27: 21 | C27: 45223 | D27: 303547 | F27: VIA BCA + 2,5K ADM
A28: 24 | B28: 22 | C28: 45254 | D28: 303547 | F28: VIA BCA + 2,5K ADM
A29: 25 | B29: 23 | C29: 45284 | D29: 303547 | F29: VIA BCA + 2,5K ADM
A30: 26 | B30: 24 | C30: 45315 | D30: 303547 | F30: VIA BCA + 2,5K ADM
A31: 27 | B31: 25 | C31: 45346 | D31: 303547 | F31: VIA BCA + 2,5K ADM
A32: 28 | B32: 26 | C32: 45375 | D32: 303547 | F32: VIA BCA + 2,5K ADM
A33: 29 | B33: 27 | C33: 45406 | D33: 303547 | F33: VIA BCA + 2,5K ADM
A34: 30 | B34: 28 | C34: 45436 | D34: 303547 | F34: VIA BCA + 2,5K ADM
A35: 31 | B35: 29 | C35: 45467 | D35: 303547 | F35: VIA BCA + 2,5K ADM
A36: 32 | B36: 30 | C36: 45497 | D36: 303547 | F36: VIA BCA + 2,5K ADM
A37: 33 | B37: 31 | C37: 45528 | D37: 303547 | F37: VIA BCA + 2,5K ADM
... A42: 38 | B42: 36 | C42: 45650 | D42: 303547 | F42: VIA BCA + 2,5K ADM
A43: Total Keseluruhan | D43: =SUM(D5:D41) -> 12068245 | E43: Note :
A44: Harga Jual Emas
A45: Laba / Rugi

Sheet LISTRIK NENEK
A1: PLN NENEK BULANAN
A4: No. | B4: Jth Tempo | C4: Nominal | D4: Paid Tgl | E4: Keterangan
A5: 1 | B5: 44464 | C5: 169675 | D5: 44458 | E5: Listrik + Adm 3rb
A6: 2 | B6: 44494 | C6: 147745 | D6: 44488 | E6: Listrik + Adm 3rb
A7: 3 | B7: 44525 | C7: 189306 | D7: 44505 | E7: Listrik + Adm 3rb
A8: 4 | B8: 44555 | C8: 136280 | D8: 44535 | E8: Listrik + Adm 3rb
A9: 5 | B9: 44586 | C9: 147745 | D9: 44566 | E9: Listrik + Adm 3rb
A10: 6 | B10: 44617 | C10: 142013 | D10: 44597 | E10: Listrik + Adm 3rb
A11: 7 | B11: 44645 | C11: 134847 | D11: 44625 | E11: Listrik + Adm 3rb
A12: 8 | B12: 44676 | C12: 147611 | D12: 44656 | E12: Listrik + Adm 3rb
A13: 9 | B13: 44706 | C13: 154911 | D13: 44686 | E13: Listrik + Adm 3rb
A14: 10 | B14: 44737 | C14: 188006 | D14: 44733 | E14: Listrik + Adm 3rb
A15: 11 | B15: 44767 | C15: 146312 | D15: 44747 | E15: Listrik + Adm 3rb
A16: 12 | B16: 44798 | C16: 167809 | D16: 44778 | E16: Listrik + Adm 3rb
... A27: 23 | B27: 45132 | C27: 253796 | D27: 44747 | E27: Listrik + Adm 3rb
A28: 24 | B28: 45163 | E28: Listrik + Adm 3rb
A29: 25 | B29: 45194 | E29: Listrik + Adm 3rb
A30: 26 | B30: 45224 | E30: Listrik + Adm 3rb
A31: 27 | B31: 45255 | E31: Listrik + Adm 3rb
A32: 28 | B32: 45285 | E32: Listrik + Adm 3rb
A33: 29 | B33: 45316 | E33: Listrik + Adm 3rb
A34: 30 | B34: 45347 | E34: Listrik + Adm 3rb
A35: 31 | B35: 45376 | E35: Listrik + Adm 3rb
A36: 32 | B36: 45407 | E36: Listrik + Adm 3rb
A37: 33 | B37: 45437 | E37: Listrik + Adm 3rb
A38: 34 | B38: 45468 | E38: Listrik + Adm 3rb
A39: 35 | B39: 45498 | E39: Listrik + Adm 3rb
... A44: 40 | B44: 45651 | E44: Listrik + Adm 3rb
C46: =SUM(C5:C44) -> 3876233

Sheet LISTRIK, IPL & AIR PMA
A1: KEBUTUHAN LISTRIK, IPL, AIR DLL PMA
A4: No. | B4: Jth Tempo | C4: Nominal | D4: Paid Tgl | E4: Keterangan
A5: 1 | B5: - | C5: 55000 | D5: 44391 | E5: Akses Mobil
A6: 2 | B6: - | C6: 60500 | D6: 44391 | E6: Other
A7: 3 | B7: - | C7: 55000 | D7: 44446 | E7: Akses Motor
A8: 4 | B8: 44459 | C8: 347404 | D8: 44446 | E8: Listrik & Air
A9: 5 | B9: 44489 | C9: 701887 | D9: 44477 | E9: Listrik & Air
A10: 6 | B10: 44520 | C10: 649650 | D10: 44505 | E10: Listrik & Air
A11: 7 | B11: 44550 | C11: 477806 | D11: 44539 | E11: Listrik & Air
A12: 8 | B12: 44581 | C12: 568447 | D12: 44567 | E12: Listrik & Air
A13: 9 | B13: 44597 | C13: 385000 | D13: 44597 | E13: Akses Patah
A14: 10 | B14: 44612 | C14: 603896 | D14: 44597 | E14: Listrik & Air
A15: 11 | B15: 44640 | C15: 584992 | D15: 44628 | E15: Listrik & Air
A16: 12 | B16: 44671 | C16: 549804 | D16: 44653 | E16: Listrik & Air
A17: 13 | B17: 44691 | C17: 55000 | D17: 44691 | E17: Other
A18: 14 | B18: 44701 | C18: 531933 | D18: 44691 | E18: Listrik & Air
A19: 15 | B19: 44720 | C19: 99900 | D19: 44704 | E19: Other
... A35: 31 | B35: 45127 | C35: 2188366 | D35: 45140 | E35: Listrik, Air & IPL 3 Bulan
A36: 32 | B36: 45158 | E36: Listrik & Air
A37: 33 | B37: 45189 | E37: Listrik & Air
A38: 34 | B38: 45219 | E38: Listrik, Air & IPL 3 Bulan
A39: 35 | B39: 45250 | E39: Listrik & Air
A40: 36 | B40: 45280 | E40: Listrik & Air
A41: 37 | B41: 45311 | E41: Listrik, Air & IPL 3 Bulan
A42: 38 | B42: 45342 | E42: Listrik & Air
A43: 39 | B43: 45371 | E43: Listrik & Air
A44: 40 | B44: 45402 | E44: Listrik, Air & IPL 3 Bulan
A45: 41 | B45: 45432 | E45: Listrik & Air
A46: 42 | B46: 45463 | E46: Listrik & Air
A47: 43 | B47: 45493 | E47: Listrik, Air & IPL 3 Bulan
... A52: 48 | B52: 45646 | E52: Listrik & Air
B55: Total Sementara | C55: =SUM(C5:C52) -> 23909674

Sheet PMA
A1: CICILAN PMA STUDIO TD31B15 15TH / 180BULAN
A4: Angsuran ke | B4: Jth Tempo | C4: Nominal | D4: Paid Tgl | E4: Nominal | F4: Keterangan
A5: Booking Fee | B5: 44324 | C5: 20000000 | D5: 44324 | E5: =C5 -> 20000000
A6: Akad | B6: 44356 | C6: 11000000 | D6: 44356 | E6: =C6 -> 11000000 | F6: Via Mandiri (Hold dana 3,909,923) Lunas di refund
A7: 1 | B7: 44389 | C7: 3909923 | D7: - | E7: =C7 -> 3909923 | F7: Cek Mutasi Mandiri
A8: 2 | B8: 44420 | C8: 3909922 | D8: - | E8: =C8 -> 3909922 | F8: Cek Mutasi Mandiri
A9: 3 | B9: 44451 | C9: 1888124 | D9: 44482 | E9: =SUM(C9:C11) -> 3909922
B10: 44451 | C10: 384347 | D10: 44483
B11: 44451 | C11: 1637451 | D11: 44483
B12: 44451 | C12: 200000 | D12: 44483 | E12: =C12 -> 200000 | F12: Late Charges
A13: 4 | B13: 44481 | C13: 705240 | D13: 44480 | E13: =SUM(C13:C15) -> 3909923
B14: 44481 | C14: 1561431 | D14: 44480
B15: 44481 | C15: 1643252 | D15: 44480
A16: 5 | B16: 44512 | C16: 2257318 | D16: 44511 | E16: =SUM(C16:C17) -> 3909923
B17: 44512 | C17: 1652605 | D17: 44511
A18: 6 | B18: 44542 | C18: 2249767 | D18: 44543 | E18: =SUM(C18:C19) -> 3909922
B19: 44542 | C19: 1660155 | D19: 44543
A20: 7 | B20: 44573 | C20: 2238370 | D20: 44572 | E20: =SUM(C20:C21) -> 3909922
B21: 44573 | C21: 1671552 | D21: 44572
A22: 8 | B22: 44604 | C22: 2195863 | D22: 44603 | E22: =SUM(C22:C23) -> 3909922
B23: 44604 | C23: 1714059 | D23: 44603
A24: 9 | B24: 44632 | C24: 2209658 | D24: 44631 | E24: =SUM(C24:C25) -> 3909923
B25: 44632 | C25: 1700265 | D25: 44631
A26: 10 | B26: 44663 | C26: 2212307 | D26: 44662 | E26: =SUM(C26:C27) -> 3909923
B27: 44663 | C27: 1697616 | D27: 44662
A28: 11 | B28: 44693 | C28: 2210083 | D28: 44692 | E28: =SUM(C28:C29) -> 3909923
B29: 44693 | C29: 1699840 | D29: 44692
A30: 12 | B30: 44724 | C30: 2202516 | D30: 44725 | E30: =SUM(C30:C31) -> 3909923
B31: 44724 | C31: 1707407 | D31: 44725
A32: 13 | B32: 44754 | C32: 2185030 | D32: 44753 | E32: =SUM(C32:C33) -> 3909923
B33: 44754 | C33: 1724893 | D33: 44753
A34: 14 | B34: 44785 | C34: 2182519 | D34: 44784 | E34: =SUM(C34:C35) -> 3909922
B35: 44785 | C35: 1727403 | D35: 44784
A36: 15 | B36: 44816 | C36: 2142762 | D36: 44816 | E36: =SUM(C36:C37) -> 3909923
B37: 44816 | C37: 1767161 | D37: 44816
A38: 16 | B38: 44846 | C38: 2098793 | D38: 44845 | E38: =SUM(C38:C39) -> 3909923
B39: 44846 | C39: 1811130 | D39: 44845
A40: 17 | B40: 44877 | C40: 1822527 | D40: 44876 | E40: =SUM(C40:C41) -> 3909922
B41: 44877 | C41: 2087395 | D41: 44876
A42: 18 | B42: 44907 | C42: 2098794 | D42: 44907 | E42: =SUM(C42:C43) -> 3909922
...

Sheet ASURANSI ASTRALIFE
A1: ANGSURAN ASURANSI 10THN / 120BULAN
A4: Angsuran ke | B4: Jth Tempo | C4: Nominal | D4: Paid Tgl | E4: Keterangan
A5: 1 | B5: 44302 | C5: 270000
A6: 2 | B6: 44332 | C6: 270000
A7: 3 | B7: 44363 | C7: 270000
A8: 4 | B8: 44393 | C8: 270000
A9: 5 | B9: 44424 | C9: 270000
A10: 6 | B10: 44455 | C10: 270000 | D10: 44455 | E10: Angsuran Sep 21
A11: 7 | B11: 44485 | C11: 270000 | D11: 44487 | E11: Angsurang Okt 21
A12: 8 | B12: 44516 | C12: 270000 | D12: 44516 | E12: Angsuran Nov 21
A13: 9 | B13: 44546 | C13: 270000 | D13: 44567 | E13: Angsuran Des 21 +Late Charge
A14: 10 | B14: 44577 | C14: 270000 | D14: 44578 | E14: Angsurang Jan 22
A15: 11 | B15: 44608 | C15: 270000 | D15: 44608 | E15: Angsuran Feb 22
A16: 12 | B16: 44636 | C16: 270000 | D16: 44636 | E16: Angsuran Mar 22
A17: 13 | B17: 44667 | C17: 270000 | D17: 44690 | E17: Angsuran Apr 22 + Late Charge
A18: 14 | B18: 44697 | C18: 270000 | D18: 44698 | E18: Angsuran Mei 22
A19: 15 | B19: 44728 | C19: 270000 | D19: 44728 | E19: Angsurang Jun 22
A20: 16 | B20: 44758 | C20: 270000 | D20: 44760 | E20: Angsurang Jul 22
A21: 17 | B21: 44789 | C21: 270000 | D21: 44789 | E21: Angsurang Aug 22
... A32: 28 | B32: 45123 | C32: 270000 | D32: 45124 | E32: Angsuran Jul 23 + Late Charge
A33: 29 | B33: 45154 | C33: 270000
A34: 30 | B34: 45185 | C34: 270000
A35: 31 | B35: 45215 | C35: 270000
A36: 32 | B36: 45246 | C36: 270000
A37: 33 | B37: 45276 | C37: 270000
A38: 34 | B38: 45307 | C38: 270000
A39: 35 | B39: 45338 | C39: 270000
A40: 36 | B40: 45367 | C40: 270000
A41: 37 | B41: 45398 | C41: 270000
A42: 38 | B42: 45428 | C42: 270000
A43: 39 | B43: 45459 | C43: 270000
A44: 40 | B44: 45489 | C44: 270000
... A124: 120 | B124: 47923 | C124: 270000

Sheet MSR JAN 2023 (AAE-ARL)
A1: MSR JANUARI 2023
A2: Marketing : IKA
A3: PERIODR 01-31 JANUARI 2023
A4: IMPORT
A5: NO | B5: REFF NO | C5: DESCRIPTION | D5: CUSTOMER | E5: NO. B/L | F5: ORIGIN | G5: ETA | H5: BUYING | I5: SELLING | J5: PROFIT | K5: PAYMENT DATE | L5: ACCOUNT
A7: 1 | B7: 009/IMP/I/23 | C7: CUSTOM CLEARANCE & TRUCKING 4X40HQ | D7: PT. BERCA MANDIRI PERKASA | E7: 008CX66413 | F7: KOBE | G7: 44936 | H7: 8800000 | I7: 11550000 | J7: =I7-H7 -> 2750000 | K7: 45000 | L7: ANTILLIA
A8: 2 | B8: 010/IMP/I/23 | C8: CUSTOM CLEARANCE & TRUCKING 3X40HQ | D8: PT. BERCA MANDIRI PERKASA | E8: 008CX64787 | F8: KOBE | G8: 44941 | H8: 6600000 | I8: 8750000 | J8: =I8-H8 -> 2150000 | K8: 45000 | L8: ANTILLIA
A9: 3 | B9: 17601/IMP/I/23 | C9: OF EXW, CUSTOM CLEARANCE & TRUCKING LCL | D9: PT. BERCA MANDIRI PERKASA | E9: X22-10623-JKT-005 | F9: SINGAPORE | G9: 44944 | H9: 7279790.5 | I9: 15223868 | J9: =I9-H9 -> 7944078 | K9: 45000 | L9: ATLANTIK
A10: 4 | B10: 3022/IMP/I/23 | C10: CUSTOM CLEARANCE & TRUCKING 1X40HQ | D10: PT. ARYASATYA MAKMUR LESTARI | E10: SNKO101230100179 | F10: HO CHI MINH | G10: 44940 | H10: 2750000 | I10: 3650000 | J10: =I10-H10 -> 900000 | K10: 44964 | L10: ATLANTIK
A11: 5 | B11: 00002/IMP/I/23 | C11: OF EXWORK IMPORT NEW DELHI TO JAKARTA | D11: PT. TRUELOGS GEO ENERGI | E11: 320113000037 | F11: NEW DELHI | G11: 44961 | H11: 12809512 | I11: 29145905 | J11: =I11-H11 -> 16336393 | K11: 45016 | L11: ANTILLIA
A12: 6 | B12: 012/IMP/I/23 | C12: TRUCKING ONLY | D12: PT. TRACLINEOO UTAMA INDONESIA | E12: COAU7884525680 | F12: TIANJIN | G12: 44956 | H12: 18241664 | I12: 25479164 | J12: =I12-H12 -> 7237500 | K12: 45026 | L12: ANTILLIA
F13: Total Profit Import | J13: =SUM(J7:J12) -> 37317971
A14: EXPORT
A15: NO | B15: REFF NO | C15: DESCRIPTION | D15: CUSTOMER | E15: NO. B/L | F15: DESTINASI | G15: ETA | H15: BUYING | I15: SELLING | J15: PROFIT | K15: PAYMENT DATE | L15: ACCOUNT
A17: 7 | B17: 001/CX/I/2023 | C17: CUSTOM EXPORT & TRUCKING | D17: PT. BINA NIAGA MULTIUSAHA | E17: KMTCJKT4362976 | F17: HAIPHONG - VIETNAM | G17: 44967 | H17: 2718021 | I17: 3468021 | J17: =I17-H17 -> 750000 | K17: 45022 | L17: ANTILLIA
A18: 8 | B18: 002/CX/I/2023 | C18: CUSTOM EXPORT & TRUCKING | D18: PT. BINA NIAGA MULTIUSAHA | E18: PGBG0109099472 | F18: NEW YORK | G18: 45002 | H18: 1750000 | I18: 2500000 | J18: =I18-H18 -> 750000 | K18: 45022 | L18: ANTILLIA
F19: Total Profit Export | J19: =SUM(J17:J17) -> 750000
F20: Total Export Import | J20: =J13+J19 -> 38067971
F21: Target Marketing | J21: 36000000
F23: Total Komisi 12,5% | J23: =J20*12.5/100 -> 4758496.4
F25: Total Komisi IKA | J25: =SUM(J23:J23) -> 4758496.4

Sheet MSR FEB 2023 (AAE-ARL)
A1: MSR FEBRUARI 2023
A2: Marketing : IKA
A3: PERIODR 01-28 FEBRUARI 2023
A4: IMPORT
A5: NO | B5: REFF NO | C5: DESCRIPTION | D5: CUSTOMER | E5: NO. B/L | F5: ORIGIN | G5: ETA | H5: BUYING | I5: SELLING | J5: PROFIT | L5: ACCOUNT
A7: 1 | B7: 013/IMP/II/23 | C7: IMPORT TRUCKING ONLY | D7: PT. ELANG CAKRAWALA INDONESIA - PT. MITRA ANTARA KARGO | E7: COAU8029546880 | F7: XIAOLAN | G7: 44965 | H7: 4510000 | I7: 5310000 | J7: =I7-H7 -> 800000 | L7: ANTILLIA
A8: 2 | B8: 3026/IMP/23 | C8: IMPORT CC | D8: PT. ARYASATYA MAKMUR LESTARI | E8: SGNCB23001902 | F8: HO CHI MINH | G8: 44970 | H8: 3144660 | I8: 3994660 | J8: =I8-H8 -> 850000 | L8: ATLANTIK
A9: 3 | B9: 3027/IMP/23 | C9: IMPORT CC | D9: PT. ARYASATYA MAKMUR LESTARI | E9: SGNCB23002330 | F9: HO CHI MINH | G9: 44978 | H9: 3844660 | I9: 5994660 | J9: =I9-H9 -> 2150000 | L9: ATLANTIK
A10: 4 | B10: 3029/IMP/23 | C10: IMPORT, TRUCKING & CC | D10: PT. DELISARI NUSANTARA | E10: COAU7243138400 | F10: PASIR GUDANG - MALAYSIA | G10: 44982 | H10: 2232700 | I10: 4197700 | J10: =I10-H10 -> 1965000 | L10: ATLANTIK
A11: 5 | B11: 3030/IMP/23 | C11: IMPORT CC | D11: PT. ARYASATYA MAKMUR LESTARI | E11: HASL21230201182 | F11: HO CHI MINH | G11: 44983 | H11: 2100000 | I11: 2950000 | J11: =I11-H11 -> 850000 | L11: ATLANTIK
F12: Total Profit Import | J12: =SUM(J7:J11) -> 6615000
A13: EXPORT
A14: NO | B14: REFF NO | C14: DESCRIPTION | D14: CUSTOMER | E14: NO. B/L | F14: DESTINASI | G14: ETA | H14: BUYING | I14: SELLING | J14: PROFIT
A16: - | B16: - | C16: - | D16: - | E16: - | F16: - | G16: - | H16: - | I16: - | J16: 0
F17: Total Profit Export | J17: =SUM(J16:J16) -> 0
F18: Total Export Import | J18: =J12+J17 -> 6615000
F19: Target Marketing | J19: 36000000
F20: Selisih Target | J20: =J19-J18 -> 29385000
F21: Total Komisi 12,5% | J21: =J18*12.5/100 -> 826875
F23: Total Komisi IKA | J23: =SUM(J21:J21) -> 826875

Sheet MSR MARCH 2023 (AAE-ARL)
A1: MSR MARET 2023
A2: Marketing : IKA
A3: PERIODR 01-31 MARCH 2023
A4: IMPORT
A5: NO | B5: REFF NO | C5: DESCRIPTION | D5: CUSTOMER | E5: NO. B/L | F5: ORIGIN | G5: ETA | H5: BUYING | I5: SELLING | J5: PROFIT | L5: ACCOUNT
A7: 1 | B7: 3033/IMP/23 | C7: CUSTOM & TRUCKING | D7: PT. BERCA MANDIRI PERKASA | E7: SISS23086732 | F7: SINGAPORE | G7: 44986 | H7: 1025000 | I7: 2750000 | J7: =I7-H7 -> 1725000 | L7: ATLANTIK
A8: 2 | B8: 014/IMP/III/23 | C8: CUSTOM & TRUCKING | D8: PT. BERCA MANDIRI PERKASA | E8: SISS23087487 | F8: SINGAPORE | G8: 44998 | H8: 875000 | I8: 2750000 | J8: =I8-H8 -> 1875000 | L8: ANTILLIA
A9: 3 | B9: 01/IMP/III/23 | C9: IMPORT AF BY AIR | D9: PT. PRIMAPLAST STRAW | E9: 235-49892673 | F9: ISTANBUL | G9: 44988 | H9: 13615956 | I9: 18877000 | J9: 5261044 | L9: ANTILLIA
A10: 4 | B10: 3039/IMP/23 | C10: IMPORT OF, CC & TRUCKING | D10: PT. BERCA MANDIRI PERKASA | E10: X23-01649-JKT-003 | F10: SINGAPORE | G10: 44992 | H10: 12639066 | I10: 15944465 | J10: =I10-H10 -> 3305399 | L10: ATLANTIK
A11: 5 | B11: 3034/IMP/23 | C11: CUSTOM & TRUCKING | D11: PT. ARYASATYA MAKMUR LESTARI | E11: SGNCB23003578 | F11: HO CHI MINH | G11: 44993 | H11: 5000160 | I11: 6850160 | J11: =I11-H11 -> 1850000 | L11: ATLANTIK
A12: 6 | B12: 3038/IMP/23 | C12: CUSTOM & TRUCKING | D12: PT. FECALINDO DINAMIKA INTIPRIMA | E12: PRG0166247 | F12: HAMBURG | G12: 44998 | H12: 5750000 | I12: 9325000 | J12: =I12-H12 -> 3575000 | L12: ATLANTIK
A13: 7 | B13: 3036/IMP/24 | C13: CUSTOM & TRUCKING | D13: PT. ARYASATYA MAKMUR LESTARI | E13: MUN331654JKR | F13: MUNDRA | G13: 44999 | H13: 1850000 | I13: 2900000 | J13: =I13-H13 -> 1050000 | L13: ATLANTIK
A14: 8 | B14: 017/IMP/III/23 | C14: CUSTOM & TRUCKING | D14: PT. BERCA MANDIRI PERKASA | E14: TAOJKTN20004 | F14: QINGDAO | G14: 45000 | H14: 1025000 | I14: 2750000 | J14: =I14-H14 -> 1725000 | L14: ANTILLIA
A15: 9 | B15: 018/IMP/III/23 | C15: TALANGAN INV ONLY | D15: PT. BERCA MANDIRI PERKASA | E15: 914876507 | F15: SHANGHAI | G15: 45001 | H15: 81307350 | I15: 84419500 | J15: =I15-H15 -> 3112150 | L15: ANTILLIA
A16: 10 | B16: 015/IMP/III/23 | C16: CUSTOM & TRUCKING | D16: PT. DELISARI NUSANTARA | E16: ONEYJHBD02568500 | F16: PASIR GUDANG | G16: 45009 | H16: 1750000 | I16: 3565000 | J16: =I16-H16 -> 1815000 | L16: ANTILLIA
A17: 11 | B17: 016/IMP/III/23 | C17: CUSTOM & TRUCKING | D17: PT. BERCA MANDIRI PERKASA | E17: LGZJKT2322344 | F17: GUANGZHOU | G17: 45010 | H17: 975000 | I17: 2750000 | J17: =I17-H17 -> 1775000 | L17: ANTILLIA
A18: 12 | B18: 3040/IMP/23 | C18: CUSTOM & TRUCKING | D18: PT. DELISARI NUSANTARA | E18: CMZ1055501 | F18: QINZHOU | G18: 45012 | H18: 1950000 | I18: 4815000 | J18: =I18-H18 -> 2865000 | L18: ATLANTIK
F19: Total Profit Import | J19: =SUM(J7:J18) -> 29933593
A20: EXPORT
A21: NO | B21: REFF NO | C21: DESCRIPTION | D21: CUSTOMER | E21: NO. B/L | F21: DESTINASI | G21: ETD | H21: BUYING | I21: SELLING | J21: PROFIT
A23: 13 | B23: 0021/EXP/III/23 | C23: OF, TRUCK & CUSTOM | D23: PT. POLYCHEMIE ASIA PACIFIC PERMAI | E23: MEJKT,10,009292 | F23: HOCHIMINCH | G23: 44999 | H23: 5522160 | I23: 9832500 | J23: =I23-H23 -> 4310340 | L23: ANTILLIA
A24: 14 | B24: 0022/EXP/III/23 | C24: TRUCK & EMKL SBY | D24: SH: PT. GUNTNER INDONESIA / PT. OBOR INDONESIA | E24: COSU6890767100 | F24: APAPA - SURABAYA | G24: 45008 | H24: 6500000 | I24: 12853480 | J24: =I24-H24 -> 6353480 | L24: ANTILLIA
A25: 15 | B25: 0020/EXP/III/23 | C25: OF, TRUCK & CUSTOM | D25: PT. POLYCHEMIE ASIA PACIFIC PERMAI | E25: ARL/JKT/LCL/PKG/0019/23 | F25: PORTKLANG | G25: 45008 | H25: 3538860 | I25: 7003050 | J25: =I25-H25 -> 3464190 | L25: ANTILLIA
F26: Total Profit Export | J26: =SUM(J23:J25) -> 14128010
F28: Total Export Import | J28: =J19+J26 -> 44061603
F29: Target Marketing | J29: 36000000
F31: Total Komisi 12,5% | J31: =J28*12.5/100 -> 5507700.4

Sheet MSR JAN TILL MAR
A1: MSR IKA
A2: PERIODE JANUARI S/D MARET 2023
A3: IMPORT
A4: NO | B4: REFF NO | C4: DESCRIPTION | D4: CUSTOMER | E4: NO. B/L | F4: ORIGIN | G4: ETA | H4: BUYING | I4: SELLING | J4: PROFIT | K4: PAYMENT DATE | L4: ACCOUNT
A6: JANUARI
A7: 1 | B7: 009/IMP/I/23 | C7: CUSTOM CLEARANCE & TRUCKING 4X40HQ | D7: PT. BERCA MANDIRI PERKASA | E7: 008CX66413 | F7: KOBE | G7: 44936 | H7: 8800000 | I7: 11550000 | J7: =I7-H7 -> 2750000 | K7: 45000 | L7: ANTILLIA
A8: 2 | B8: 010/IMP/I/23 | C8: CUSTOM CLEARANCE & TRUCKING 3X40HQ | D8: PT. BERCA MANDIRI PERKASA | E8: 008CX64787 | F8: KOBE | G8: 44941 | H8: 6600000 | I8: 8750000 | J8: =I8-H8 -> 2150000 | K8: 45000 | L8: ANTILLIA
A9: 3 | B9: 17601/IMP/I/23 | C9: OF EXW, CUSTOM CLEARANCE & TRUCKING LCL | D9: PT. BERCA MANDIRI PERKASA | E9: X22-10623-JKT-005 | F9: SINGAPORE | G9: 44944 | H9: 7279790.5 | I9: 15223868 | J9: =I9-H9 -> 7944078 | K9: 45000 | L9: ATLANTIK
A10: 4 | B10: 3022/IMP/I/23 | C10: CUSTOM CLEARANCE & TRUCKING 1X40HQ | D10: PT. ARYASATYA MAKMUR LESTARI | E10: SNKO101230100179 | F10: HO CHI MINH | G10: 44940 | H10: 2750000 | I10: 3650000 | J10: =I10-H10 -> 900000 | K10: 44964 | L10: ATLANTIK
A11: 5 | B11: 00002/IMP/I/23 | C11: OF EXWORK IMPORT NEW DELHI TO JAKARTA | D11: PT. TRUELOGS GEO ENERGI | E11: 320113000037 | F11: NEW DELHI | G11: 44961 | H11: 12809512 | I11: 29145905 | J11: =I11-H11 -> 16336393 | K11: 45016 | L11: ANTILLIA
A12: 6 | B12: 012/IMP/I/23 | C12: TRUCKING ONLY | D12: PT. TRACLINEOO UTAMA INDONESIA | E12: COAU7884525680 | F12: TIANJIN | G12: 44956 | H12: 18241664 | I12: 25479164 | J12: =I12-H12 -> 7237500 | K12: 45026 | L12: ANTILLIA
A13: FEBRUARI
A14: 1 | B14: 013/IMP/II/23 | C14: IMPORT TRUCKING ONLY | D14: PT. ELANG CAKRAWALA INDONESIA - PT. MITRA ANTARA KARGO | E14: COAU8029546880 | F14: XIAOLAN | G14: 44965 | H14: 4510000 | I14: 5310000 | J14: =I14-H14 -> 800000 | K14: 45000 | L14: ANTILLIA
A15: 2 | B15: 3026/IMP/23 | C15: IMPORT CC | D15: PT. ARYASATYA MAKMUR LESTARI | E15: SGNCB23001902 | F15: HO CHI MINH | G15: 44970 | H15: 3144660 | I15: 3994660 | J15: =I15-H15 -> 850000 | K15: 45000 | L15: ATLANTIK
A16: 3 | B16: 3027/IMP/23 | C16: IMPORT CC | D16: PT. ARYASATYA MAKMUR LESTARI | E16: SGNCB23002330 | F16: HO CHI MINH | G16: 44978 | H16: 3844660 | I16: 5994660 | J16: =I16-H16 -> 2150000 | K16: 45000 | L16: ATLANTIK
A17: 4 | B17: 3029/IMP/23 | C17: IMPORT, TRUCKING & CC | D17: PT. DELISARI NUSANTARA | E17: COAU7243138400 | F17: PASIR GUDANG - MALAYSIA | G17: 44982 | H17: 2232700 | I17: 4197700 | J17: =I17-H17 -> 1965000 | K17: 44964 | L17: ATLANTIK
A18: 5 | B18: 3030/IMP/23 | C18: IMPORT CC | D18: PT. ARYASATYA MAKMUR LESTARI | E18: HASL21230201182 | F18: HO CHI MINH | G18: 44983 | H18: 2100000 | I18: 2950000 | J18: =I18-H18 -> 850000 | K18: 45016 | L18: ATLANTIK
A19: MARET
A20: 1 | B20: 3033/IMP/23 | C20: CUSTOM & TRUCKING | D20: PT. BERCA MANDIRI PERKASA | E20: SISS23086732 | F20: SINGAPORE | G20: 44986 | H20: 1025000 | I20: 2750000 | J20: =I20-H20 -> 1725000 | K20: LUNAS | L20: ATLANTIK
A21: 2 | B21: 014/IMP/III/23 | C21: CUSTOM & TRUCKING | D21: PT. BERCA MANDIRI PERKASA | E21: SISS23087487 | F21: SINGAPORE | G21: 44998 | H21: 875000 | I21: 2750000 | J21: =I21-H21 -> 1875000 | K21: LUNAS | L21: ANTILLIA
A22: 3 | B22: 01/IMP/III/23 | C22: IMPORT AF BY AIR | D22: PT. PRIMAPLAST STRAW | E22: 235-49892673 | F22: ISTANBUL | G22: 44988 | H22: 13615956 | I22: 18877000 | J22: 5261044 | K22: LUNAS | L22: ANTILLIA
A23: 4 | B23: 3039/IMP/23 | C23: IMPORT OF, CC & TRUCKING | D23: PT. BERCA MANDIRI PERKASA | E23: X23-01649-JKT-003 | F23: SINGAPORE | G23: 44992 | H23: 12639066 | I23: 15944465 | J23: =I23-H23 -> 3305399 | K23: 45033 | L23: ATLANTIK
A24: 5 | B24: 3034/IMP/23 | C24: CUSTOM & TRUCKING | D24: PT. ARYASATYA MAKMUR LESTARI | E24: SGNCB23003578 | F24: HO CHI MINH | G24: 44993 | H24: 5000160 | I24: 6850160 | J24: =I24-H24 -> 1850000 | K24: LUNAS | L24: ATLANTIK
A25: 6 | B25: 3038/IMP/23 | C25: CUSTOM & TRUCKING | D25: PT. FECALINDO DINAMIKA INTIPRIMA | E25: PRG0166247 | F25: HAMBURG | G25: 44998 | H25: 5750000 | I25: 9325000 | J25: =I25-H25 -> 3575000 | K25: 45019 | L25: ATLANTIK
A26: 7 | B26: 3036/IMP/24 | C26: CUSTOM & TRUCKING | D26: PT. ARYASATYA MAKMUR LESTARI | E26: MUN331654JKR | F26: MUNDRA | G26: 44999 | H26: 1850000 | I26: 2900000 | J26: =I26-H26 -> 1050000 | K26: LUNAS | L26: ATLANTIK
A27: 8 | B27: 017/IMP/III/23 | C27: CUSTOM & TRUCKING | D27: PT. BERCA MANDIRI PERKASA | E27: TAOJKTN20004 | F27: QINGDAO | G27: 45000 | H27: 1025000 | I27: 2750000 | J27: =I27-H27 -> 1725000 | K27: LUNAS | L27: ANTILLIA
A28: 9 | B28: 018/IMP/III/23 | C28: TALANGAN INV ONLY | D28: PT. BERCA MANDIRI PERKASA | E28: 914876507 | F28: SHANGHAI | G28: 45001 | H28: 81307350 | I28: 84419500 | J28: =I28-H28 -> 3112150 | K28: 45026 | L28: ANTILLIA
A29: 10 | B29: 015/IMP/III/23 | C29: CUSTOM & TRUCKING | D29: PT. DELISARI NUSANTARA | E29: ONEYJHBD02568500 | F29: PASIR GUDANG | G29: 45009 | H29: 1750000 | I29: 3565000 | J29: =I29-H29 -> 1815000 | K29: 45034 | L29: ANTILLIA
A30: 11 | B30: 016/IMP/III/23 | C30: CUSTOM & TRUCKING | D30: PT. BERCA MANDIRI PERKASA | E30: LGZJKT2322344 | F30: GUANGZHOU | G30: 45010 | H30: 975000 | I30: 2750000 | J30: =I30-H30 -> 1775000 | K30: 45016 | L30: ANTILLIA
A31: 12 | B31: 3040/IMP/23 | C31: CUSTOM & TRUCKING | D31: PT. DELISARI NUSANTARA | E31: CMZ1055501 | F31: QINZHOU | G31: 45012 | H31: 1950000 | I31: 4815000 | J31: =I31-H31 -> 2865000 | K31: 45042 | L31: ATLANTIK
F32: Total Profit Import | J32: =SUM(J7:J31) -> 73866564
A33: EXPORT
A34: NO | B34: REFF NO | C34: DESCRIPTION | D34: CUSTOMER | E34: NO. B/L | F34: DESTINASI | G34: ETA | H34: BUYING | I34: SELLING | J34: PROFIT | K34: PAYMENT DATE | L34: ACCOUNT
A36: JANUARI
A37: 1 | B37: 001/CX/I/2023 | C37: CUSTOM EXPORT & TRUCKING | D37: PT. BINA NIAGA MULTIUSAHA | E37: KMTCJKT4362976 | F37: HAIPHONG - VIETNAM | G37: 44967 | H37: 2718021 | I37: 3468021 | J37: =I37-H37 -> 750000 | K37: 45022 | L37: ANTILLIA
A38: 2 | B38: 002/CX/I/2023 | C38: CUSTOM EXPORT & TRUCKING | D38: PT. BINA NIAGA MULTIUSAHA | E38: PGBG0109099472 | F38: NEW YORK | G38: 45002 | H38: 1750000 | I38: 2500000 | J38: =I38-H38 -> 750000 | K38: 45022 | L38: ANTILLIA
A39: FEBRUARI
A40: MARET
B41: 0021/EXP/III/23 | C41: OF, TRUCK & CUSTOM | D41: PT. POLYCHEMIE ASIA PACIFIC PERMAI | E41: MEJKT,10,009292 | F41: HOCHIMINCH | G41: 44999 | H41: 5522160 | I41: 9832500 | J41: =I41-H41 -> 4310340 | K41: 45022 | L41: ANTILLIA
A42: 2 | B42: 0022/EXP/III/23 | C42: TRUCK & EMKL SBY | D42: SH: PT. GUNTNER INDONESIA / PT. OBOR INDONESIA | E42: COSU6890767100 | F42: APAPA - SURABAYA | G42: 45008 | H42: 6500000 | I42: 12853480 | J42: =I42-H42 -> 6353480 | K42: 45022 | L42: ANTILLIA
...

Sheet MSR APRIL 2023
A1: MSR APRIL2023
A2: Marketing : IKA
A3: PERIODE 1-30 APRIL 2023
A4: IMPORT
A5: NO | B5: REFF NO | C5: DESCRIPTION | D5: CUSTOMER | E5: NO. B/L | F5: ORIGIN | G5: ETA | H5: BUYING | I5: SELLING | J5: PROFIT | L5: ACCOUNT
A7: 1 | B7: 00005/IMP/III/23 | C7: IMPORT - OF & CC | D7: PT. BERCA MANDIRI PERKASA | E7: AWSJKT124632 / YMLUI450448655 | F7: SINGAPORE | G7: 45017 | H7: 27833324 | I7: 34353310 | J7: =I7-H7 -> 6519986 | L7: ANTILLIA
A8: 2 | B8: 00003/IMP/III/23 | C8: IMPORT, OF & CC | D8: PT. POLYCHEMIE ASIA PACIFIC PERMAI | E8: S00215842 / COAU8036158210 | F8: SHANGHAI | G8: 45019 | H8: 6307300 | I8: 10225000 | J8: =I8-H8 -> 3917700 | L8: ANTILLIA
A9: 3 | B9: 019/IMP/III/23 | C9: JUST INVOICE | D9: PT. BERCA MANDIRI PERKASA | E9: YMLUI236297936 | F9: SHANGHAI | G9: 45019 | H9: 114836000 | I9: 121763010 | J9: =I9-H9 -> 6927010 | L9: ANTILLIA
A10: 4 | B10: 02/IMP/IV/2023 | C10: IMPORT CC | D10: PT. NATA KIMINDO PRATAMA | E10: 784-38399561 | F10: SHENZEN | G10: 45023 | H10: 140000 | I10: 1400500 | J10: =I10-H10 -> 1260500 | L10: ANTILLIA
A11: 5 | B11: 01/IMP/IV/23 | C11: IMPORT, OF & CC | D11: PT. POLYCHEMIE ASIA PACIFIC PERMAI | E11: WS230400017 / 695-41501456 | F11: XIAMEN | G11: 45025 | H11: 194838000 | I11: 265247000 | J11: =I11-H11 -> 70409000 | L11: ANTILLIA
A12: 6 | B12: 020/IMP/IV/23 | C12: IMPORT CC | D12: PT. ARYASATYA MAKMUR LESTARI | E12: SGNCB23006190 | F12: HOCHIMINCH | G12: 45026 | H12: 1750000 | I12: 2800000 | J12: =I12-H12 -> 1050000 | L12: ANTILLIA
A13: 7 | B13: 021/IMP/IV/23 | C13: IMPORT, TRUCKING & CC | D13: PT. DELISARI NUSANTARA | E13: ONEYJHBD03736300 | F13: PASIR GUDANG | G13: 45026 | H13: 1650000 | I13: 3565000 | J13: =I13-H13 -> 1915000 | L13: ANTILLIA
A14: 8 | B14: 00004/IMP/III/23 | C14: IMPORT, TRUCKING & CC | D14: PT. BERINGIN MITRA GUNA | E14: S00216264 / OOLU2715967310 | F14: SHANTOU | G14: 45028 | H14: 4500000 | I14: 13876250 | J14: =I14-H14 -> 9376250 | L14: ANTILLIA
A15: 9 | B15: 0022/IMP/IV/23 | C15: IMPORT, TRUCKING & CC | D15: PT. CITRA JAYA HOSINDO | E15: WFLQDCJKT23032237 | F15: QINGDAO | G15: 45029 | H15: 5192788 | I15: 6567788 | J15: =I15-H15 -> 1375000 | L15: ANTILLIA
A16: 10 | B16: 024/IMP/IV/23 | C16: IMPORT | D16: PT. BERCA MANDIRI PERKASA | E16: CEM0101191 | F16: DALIAN - CHINA | G16: 45029 | H16: 27800000 | I16: 37700000 | J16: =I16-H16 -> 9900000 | L16: ANTILLIA
A17: 11 | B17: 023/IMP/IV/23 | C17: INVOICE ALISPED & CUSTOM | D17: PT. BERCA MANDIRI PERKASA | E17: 226222927 | F17: SHANGHAI | G17: 45029 | H17: 23400000 | I17: 28075900 | J17: =I17-H17 -> 4675900 | L17: ANTILLIA
A18: 12 | B18: 025/IMP/IV/23 | C18: IMPORT, CC & TRUCK | D18: PT. BERCA MANDIRI PERKASA | E18: COAU8034361490 | F18: DALIAN - CHINA | G18: 45036 | H18: 5800000 | I18: 8650000 | J18: =I18-H18 -> 2850000 | L18: ANTILLIA
A19: 13 | B19: 026/IMP/IV /23 | C19: IMPORT, CC & TRUCK | D19: PT. BERCA MANDIRI PERKASA | E19: COAU7243633300 | F19: DALIAN - CHINA | G19: 45036 | H19: 11600000 | I19: 16900000 | J19: =I19-H19 -> 5300000 | L19: ANTILLIA
A20: 14 | B20: 032/IMP/IV/23 | C20: IMPORT CC | D20: PT. ARYASATYA MAKMUR LESTARI | E20: 144DX03316 | F20: CHENNAI - INDIA | G20: 45044 | H20: 4500000 | I20: 6450000 | J20: =I20-H20 -> 1950000 | L20: ANTILLIA
A21: 15 | B21: 029/IMP/IV/23 | C21: INVOICE ALISPED & CUSTOM | D21: PT. BERCA MANDIRI PERKASA | E21: 226376719 | F21: SHANGHAI | G21: 45044 | H21: 59750000 | I21: 66381500 | J21: =I21-H21 -> 6631500 | L21: ANTILLIA
A22: 16 | B22: 028/IMP/IV/23 | C22: INVOICE ALISPED & CUSTOM | D22: PT. BERCA MANDIRI PERKASA | E22: 226373665 | F22: SHANGHAI | G22: 45044 | H22: 47800000 | I22: 56785200 | J22: =I22-H22 -> 8985200 | L22: ANTILLIA
A23: 17 | B23: 030/IMP/IV/23 | C23: INVOICE ALISPED & CUSTOM | D23: PT. BERCA MANDIRI PERKASA | E23: 226373780 | F23: SHANGHAI | G23: 45044 | H23: 35950000 | I23: 39988900 | J23: =I23-H23 -> 4038900 | L23: ANTILLIA
A24: 18 | B24: 031/IMP/IV/23 | C24: INVOICE ALISPED & CUSTOM | D24: PT. BERCA MANDIRI PERKASA | E24: 226373746 | F24: SHANGHAI | G24: 45044 | H24: 119500000 | I24: 132363000 | J24: =I24-H24 -> 12863000 | L24: ANTILLIA
F25: Total Profit Import | J25: =SUM(J7:K24) -> 159944946
A26: EXPORT
A27: NO | B27: REFF NO | C27: DESCRIPTION | D27: CUSTOMER | E27: NO. B/L | F27: DESTINASI | G27: ETD | H27: BUYING | I27: SELLING | J27: PROFIT
A29: 19 | B29: 003/CX/23 | C29: TRUCKING ONLY | D29: PT. Belva Transtama Abadi / Sh: PT. Diza Aishwarya Global | E29: ARM0293828 | F29: LIANHUSHAN-CHINA | G29: 45029 | H29: 1600000 | I29: 2100000 | J29: =I29-H29 -> 500000 | L29: ANTILLIA
F30: Total Profit Export | J30: =SUM(J29) -> 500000
A31: LOKAL / DOMESTIK
A32: NO | B32: REFF NO | C32: DESCRIPTION | D32: CUSTOMER | E32: NO. B/L | F32: DESTINASI | G32: ETD | H32: BUYING | I32: SELLING | J32: PROFIT
A34: 20 | B34: 003/OTH/23 | C34: LOKAL TRUCK ONLY | D34: PT. CITRA NIAGA LOGISTIK / RADHIKA CARGO SERVICE | E34: BJKTC23012281 | F34: JKT-MAKASSAR | G34: - | H34: 3600000 | I34: 4300000 | J34: =I34-H34 -> 700000 | L34: ANTILLIA
A35: 21 | B35: 0001/DOM/IV/23 | C35: DOMESTIK | D35: PT. BERCA MANDIRI PERKASA | E35: SPK NO 048/SKPB-MSD-HE/IV/2023 | F35: JKT-BANJARMASIN | G35: 45029 | H35: 64200000 | I35: 81000000 | J35: =I35-H35 -> 16800000 | L35: ANTILLIA
F36: Total Profit Domestik | J36: =SUM(J34:J35) -> 17500000
F38: Total Export Import & Domestik | J38: =J25+J30+J36 -> 177944946
F39: Target Marketing | J39: 36000000
F40: Deduct Berca | J40: 5000000
J41: =J38-J40 -> 172944946
F43: Total Komisi 12,5% | J43: =J38*12.5/100 -> 22243118
J44: =J41*12.5/100 -> 21618118 | L44: lunas 27/07/2023

Sheet MSR MEI 2023
A1: MSR MAY 2023
A2: Marketing : IKA
A3: PERIODE 1-31 MAY 2023
A4: IMPORT
A5: NO | B5: REFF NO | C5: DESCRIPTION | D5: CUSTOMER | E5: NO. B/L | F5: ORIGIN | G5: ETA | H5: PAYMENT DATE | I5: BUYING | J5: SELLING | K5: PROFIT
A7: 1 | B7: 033/IMP/IV/23 | C7: IMPORT, CC & TRUCK | D7: PT. ARYASATYA MAKMUR LESTARI | E7: KMTCSGN4661962 | F7: HOCHIMINCH | G7: 45048 | H7: 45128 | I7: 2710450 | J7: 3560450 | K7: =J7-I7 -> 850000
A8: 2 | B8: 034/IMP/IV/23 | C8: IMPORT INV, CC & TRUCK | D8: PT. BERCA MANDIRI PERKASA | E8: 914906633 | F8: SHANGHAI | G8: 45050 | H8: 31/05/2023 OF & 17/07/2023 CC | I8: 58150000 | J8: 64510000 | K8: =J8-I8 -> 6360000
A9: 3 | B9: 011/IMP/IV/23 | C9: IMPORT, OF & CUSTOM | D9: PT. BERCA MANDIRI PERKASA | E9: WS23040084/CMZ1081293 | F9: SHEKOU | G9: 45053 | H9: 45140 | I9: 34535000 | J9: 51300830 | K9: =J9-I9 -> 16765830
A10: 4 | B10: 001/IMP/V/23 | C10: IMPORT CC | D10: PT. BERCA MANDIRI PERKASA | E10: GTD0776598 | F10: LAEM CHABANG - THAILAND | G10: 45054 | H10: 45134 | I10: 4200000 | J10: 6200000 | K10: =J10-I10 -> 2000000
A11: 5 | B11: 035/IMP/IV/23 | C11: IMPORT INV, CC & TRUCK | D11: PT. BERCA MANDIRI PERKASA | E11: 226906048 | F11: SHANGHAI | G11: 45057 | H11: 31/05/2023 OF & 17/07/2023 CC | I11: 34950000 | J11: 39988900 | K11: =J11-I11 -> 5038900
A12: 6 | B12: 027/IMP/IV/23 | C12: IMPORT, TRUCKING & CC | D12: PT. DELISARI NUSANTARA | E12: OOLU2139437570 | F12: ANTWERPEN | G12: 45060 | H12: 45113 | I12: 4050000 | J12: 6190000 | K12: =J12-I12 -> 2140000
A13: 7 | B13: 002/IMP/V/23 | C13: IMPORT, CC & TRUCK | D13: PT. ARYASATYA MAKMUR LESTARI | E13: CNICB23006450001 | F13: CHENAI | G13: 45061 | H13: 45128 | I13: 1950000 | J13: 3200000 | K13: =J13-I13 -> 1250000
A14: 8 | B14: 006/IMP/V/23 | C14: IMPORT CUSTOM AND TRUCK | D14: PT. CITRA PERDANA PUTRA | E14: TSNA59929200 | F14: XINGGANG | G14: 45064 | H14: 45162 | I14: 3350000 | J14: 4150000 | K14: =J14-I14 -> 800000
A15: 9 | B15: 036/IMP/IV/23 | C15: IMPORT, TRUCKING & CC | D15: PT. DELISARI NUSANTARA | E15: DELJAK210530 | F15: ICD TKD NEW DELHI | G15: 45066 | H15: 45128 | I15: 975000 | J15: 3825000 | K15: =J15-I15 -> 2850000
A16: 10 | B16: 008/IMP/V/23 | C16: IMPORT, CC & TRUCK | D16: PT. ARYASATYA MAKMUR LESTARI | E16: HASLS21230500344 | F16: HOCHIMINCH | G16: 45067 | H16: 45128 | I16: 1750000 | J16: 2800000 | K16: =J16-I16 -> 1050000
A17: 11 | B17: 010/IMP/V/23 | C17: IMPORT INV, CC & TRUCK | D17: PT. BERCA MANDIRI PERKASA | E17: SNKO190230403352 | F17: LAEM CHABANG - THAILAND | G17: 45069 | H17: 45145 | I17: 8900000 | J17: 17800000 | K17: =J17-I17 -> 8900000
A18: 12 | B18: 003/IMP/V/23 | C18: IMPORT INV, CC & TRUCK | D18: PT. BERCA MANDIRI PERKASA | E18: 227090974 | F18: SHANGHAI | G18: 45071 | H18: 45145 | I18: 88400000 | J18: 102399840 | K18: =J18-I18 -> 13999840
A19: 13 | B19: 009/IMP/V/23 | C19: IMPORT, CC & TRUCK | D19: PT. ARYASATYA MAKMUR LESTARI | E19: CNICB2300694402 | F19: CHENAI | G19: 45074 | H19: 45129 | I19: 1700000 | J19: 2800000 | K19: =J19-I19 -> 1100000
A20: 14 | B20: 012/IMP/V/23 | C20: IMPORT INV, CC & TRUCK | D20: PT. BERCA MANDIRI PERKASA | E20: GTD0782596 | F20: LAEM CHABANG - THAILAND | G20: 45075 | H20: 45145 | I20: 8100000 | J20: 11600000 | K20: =J20-I20 -> 3500000
A21: 15 | B21: 03/IMP/V/23 | C21: IMPORT CC | D21: PT. NATA KIMINDO PRATAMA | E21: 205-20968356 | F21: SHANGHAI | G21: 45076 | H21: 19/07/2023 | I21: 260000 | J21: 1371000 | K21: =J21-I21 -> 1111000
A22: 16 | B22: 005/IMP/V/23 | C22: IMPORT JASA EDIT & STAMP ONLY | D22: PT. SINERGI MANDIRI SELARAS | E22: H700204875 / GEN102157 | F22: GENOA | G22: - | H22: 45072 | I22: 180000 | J22: 1050000 | K22: =J22-I22 -> 870000
A23: 17 | B23: 004/IMP/V/23 | C23: IMPORT JASA EDIT & STAMP ONLY | D23: PT. SINERGI MANDIRI SELARAS | E23: MX/19/802568 / ONEYGOAV38152500 | F23: GENOVA | G23: - | H23: 45072 | I23: 180000 | J23: 1050000 | K23: =J23-I23 -> 870000
A24: 18 | B24: 006/IMP/23 | C24: TRUCK ONLY NON PPN | D24: PT. KARUNIA MAS SEWATAMA / TUNAS SUMBER | E24: 226484187 | F24: SHANGHAI | G24: - | H24: 45065 | I24: 1700000 | J24: 1900000 | K24: =J24-I24 -> 200000
F25: Total Profit Import | K25: =SUM(K7:K24) -> 69655570
A26: EXPORT
A27: NO | B27: REFF NO | C27: DESCRIPTION | D27: CUSTOMER | E27: NO. B/L | F27: DESTINASI | G27: ETD | H27: PAYMENT DATE | I27: BUYING | J27: SELLING | K27: PROFIT
A29: 19 | B29: 002A/EXP/V/23 | C29: EXPORT, COO ONLY | D29: SH: PT. TUNAS SUMBER IDEAKREASI KIMIA FW: TRACLINEOO | E29: SHJK230028PK | F29: PORT KELANG NORTH | G29: 45047 | H29: 14/06/2023 | I29: 200000 | J29: 550000 | K29: =J29-I29 -> 350000
A30: 20 | B30: 006/OTH/23 | C30: EXPORT CUSTOM | D30: PT. OBOR INDONESIA PRATAMA | E30: 049DX03763 | F30: XIAMEN | G30: 45060 | H30: 45163 | I30: 2000000 | J30: 5500000 | K30: =J30-I30 -> 3500000
A31: 21 | B31: 009/OTH/23 | C31: EXPORT CUSTOM | D31: PT. OBOR INDONESIA PRATAMA | E31: 049DX03975 | F31: SHANGHAI | G31: 45067 | H31: 45163 | I31: 900000 | J31: 3100000 | K31: =J31-I31 -> 2200000
A32: 22 | B32: 008/OTH/23 | C32: EXPORT CUSTOM | D32: PT. OBOR INDONESIA PRATAMA | E32: 049DX03974 | F32: XIAMEN | G32: 45067 | H32: 45163 | I32: 1550000 | J32: 4600000 | K32: =J32-I32 -> 3050000
A33: 23 | B33: 010/OTH/23 | C33: EXPORT CUSTOM & TRUCK | D33: PT. BINA NIAGA MULTIUSAHA | E33: OERT110702M00610 | F33: NEW YORK | G33: 45074 | H33: 45145 | I33: 1650000 | J33: 2600000 | K33: =J33-I33 -> 950000
F34: Total Profit Export | K34: =SUM(K29:K33) -> 10050000
A35: LOKAL / DOMESTIK
A36: NO | B36: REFF NO | C36: DESCRIPTION | D36: CUSTOMER | E36: NO. B/L | F36: DESTINASI | G36: ETD | H36: PAYMENT DATE | I36: BUYING | J36: SELLING | K36: PROFIT
A38: 24 | B38: 002/DOM/IV/23 | C38: DOMESTIK | D38: PT. BERCA MANDIRI PERKASA | E38: SPK NO 052/SKPB-MSD-HE/IV/2023 | F38: JKT-BALI | G38: 45048 | H38: 45090 | I38: 12000000 | J38: 16000000 | K38: =J38-I38 -> 4000000
A39: 25 | B39: 00003/DOM/V/23 | C39: DOMESTIK | D39: PT. BERCA MANDIRI PERKASA | E39: SPK NO 110/SKPB-MSD-MH/V/2023 | F39: JATAKE-JAMBI | G39: 45072 | H39: 45090 | I39: 12000000 | J39: 14000000 | K39: =J39-I39 -> 2000000
A40: 26 | B40: 005/OTH/23 | C40: DOMESTIK | D40: PT. OBOR INDONESIA PRATAMA | E40: BIT1023042000001 | F40: BITUNG-JKT | G40: 45035 | H40: 45163 | I40: 2850000 | J40: 4950000 | K40: =J40-I40 -> 2100000
A41: 27 | B41: 007/OTH/23 | C41: DOMESTIK | D41: PT. OBOR INDONESIA PRATAMA | E41: BIT1023050600005 | F41: BITUNG-JKT | G41: 45052 | H41: 45163 | I41: 2800000 | J41: 4950000 | K41: =J41-I41 -> 2150000
F42: Total Profit Domestik | K42: =SUM(K38:K41) -> 10250000
F44: Sisa Potongan Berca | K44: 5000000
...

Sheet MSR JUNI 2023
A1: MSR JUNI 2023
A2: Marketing : IKA
A3: PERIODE 01-30 JUNI 2023
A4: IMPORT
A5: NO | B5: REFF NO | C5: DESCRIPTION | D5: CUSTOMER | E5: NO. B/L | F5: ORIGIN | G5: ETA | H5: PAYMENT DATE | I5: BUYING | J5: SELLING | K5: PROFIT
A7: 1 | B7: 037/IMP/IV/23 | C7: IMPORT OF ONLY | D7: PT. AGRAPRANA EKSPRESS | E7: 33044547 | F7: ROTTERDAM | G7: 45080 | H7: 45083 | I7: 4131087 | J7: 8587462 | K7: =J7-I7 -> 4456375
A8: 2 | B8: 011/IMP/V/23 | C8: IMPORT CC | D8: PT. CITRA PERDANA PUTRA | E8: COAU8038084470 | F8: DALIAN | G8: 45078 | H8: 45162 | I8: 3250000 | J8: 4150000 | K8: =J8-I8 -> 900000
A9: 3 | B9: 007/IMP/V/23 | C9: IMPORT CC | D9: PT. FECALINDO DINAMIKA INTIPRIMA | E9: 52302489 | F9: HAMBURG | G9: 45080 | H9: 45103 | I9: 2500000 | J9: 4675000 | K9: =J9-I9 -> 2175000
A10: 4 | B10: 013/IMP/V/23 | C10: IMPORT CC | D10: PT. CITRA PERDANA PUTRA | E10: 292084067 | F10: XINGANG | G10: 45084 | H10: 45162 | I10: 1700000 | J10: 2275000 | K10: =J10-I10 -> 575000
A11: 5 | B11: 014/IMP/V/23 | C11: IMPORT INV ONLY | D11: PT. BERCA MANDIRI PERKASA | E11: SITGSHSRQ116404 | F11: SHANGHAI | G11: 45088 | H11: 45021 | I11: 85900000 | J11: 89814000 | K11: =J11-I11 -> 3914000
A12: 6 | B12: 002/IMP/VI/23 | C12: IMPORT, CC & TRUCK | D12: PT. ARYASATYA MAKMUR LESTARI | E12: EGLV235300605401 | F12: HO CHI MINH | G12: 45089 | I12: 2050000 | J12: 2900000 | K12: =J12-I12 -> 850000
A13: 7 | B13: 015/IMP/V/23 | C13: IMPORT CC | D13: PT. OBOR INDONESIA PRATAMA | E13: JJCSHSYA337408 | F13: SHANGHAI | G13: 45090 | I13: 9307129 | J13: 11598129 | K13: =J13-I13 -> 2291000
A14: 8 | B14: 004/IMP/VI/23 | C14: IMPORT CC | D14: PT. CITRA PERDANA PUTRA | E14: COAU8038243870 | F14: DALIAN | G14: 45092 | I14: 5150000 | J14: 6225000 | K14: =J14-I14 -> 1075000
A15: 9 | B15: 001/IMP/VI/23 | C15: IMPORT CC | D15: PT. BERCA MANDIRI PERKASA | E15: AXI0240929 | F15: XIAMEN | G15: 45093 | H15: 03/07/2023 OF & 17/07/2023 CC | I15: 41800000 | J15: 47863200 | K15: =J15-I15 -> 6063200
A16: 10 | B16: 007/IMP/V/23 | C16: IMPORT CC | D16: PT. OBOR INDONESIA PRATAMA | E16: 228113399 | F16: XIAMEN/JKT | G16: 45097 | I16: 2050000 | J16: 5300000 | K16: =J16-I16 -> 3250000
A17: 11 | B17: 006/IMP/VI/23 | C17: IMPORT CC | D17: PT. OBOR INDONESIA PRATAMA | E17: 227916291 | F17: SHANGHAI | G17: 45097 | I17: 845000 | J17: 4095000 | K17: =J17-I17 -> 3250000
A18: 12 | B18: 003/IMP/VI/23 | C18: IMPORT CC | D18: PT. BERCA MANDIRI PERKASA | E18: 227760389 | F18: SHANGHAI | G18: 45099 | H18: 02/08/2023 & 22/08/2023 | I18: 30900000 | J18: 36089000 | K18: =J18-I18 -> 5189000
A19: 13 | B19: 005/IMP/VI/23 | C19: IMPORT, TRUCKING & CC | D19: PT. DELISARI NUSANTARA | E19: OOLU8894095020 | F19: QINZHOU | G19: 45105 | H19: 45148 | I19: 1900000 | J19: 4515000 | K19: =J19-I19 -> 2615000
F20: Total Profit Import | K20: =SUM(K7:K19) -> 36603575
A21: EXPORT
A22: NO | B22: REFF NO | C22: DESCRIPTION | D22: CUSTOMER | E22: NO. B/L | F22: DESTINASI | G22: ETD | H22: PAYMENT DATE | I22: BUYING | J22: SELLING | K22: PROFIT
A24: 14 | B24: 011/OTH/23 | C24: EXPORT CC | D24: PT. BINA NIAGA MULTIUSAHA | E24: JKT300310800 | F24: LAEMCHABANG | G24: 45089 | H24: 45175 | I24: 3400000 | J24: 4650000 | K24: =J24-I24 -> 1250000
A25: 15 | B25: 013/OTH/23 | C25: EXPORT CUSTOM | D25: PT. OBOR INDONESIA PRATAMA | E25: 049DX04730 | F25: XIAMEN | G25: 45091 | H25: 45163 | I25: 1500000 | J25: 3100000 | K25: =J25-I25 -> 1600000
A26: 16 | B26: 014/OTH/23 | C26: EXPORT CUSTOM | D26: PT. OBOR INDONESIA PRATAMA | E26: 049DX04731 | F26: XIAMEN | G26: 45091 | H26: 45163 | I26: 1500000 | J26: 3100000 | K26: =J26-I26 -> 1600000
F27: Total Profit Export | K27: =SUM(K24:K26) -> 4450000
A28: LOKAL / DOMESTIK
A29: NO | B29: REFF NO | C29: DESCRIPTION | D29: CUSTOMER | E29: NO. B/L | F29: DESTINASI | G29: ETD | H29: PAYMENT DATE | I29: BUYING | J29: SELLING | K29: PROFIT
A31: 17 | B31: 004/DOM/VI/23 | C31: DOMESTIK | D31: PT. RAMADYA CAKRA SEMESTA | E31: 0106/SKPB-ARL/VI/DOM/2023 | F31: CIKARANG - KENDARI | G31: 06/06/2023 JKT 15/06/2023 SUB | H31: 45135 | I31: 20000000 | J31: 22500000 | K31: =J31-I31 -> 2500000
A32: 18 | B32: 012/OTH/23 | C32: DOMESTIK | D32: PT. OBOR INDONESIA PRATAMA | E32: BIT1023060300002 | F32: BITUNG-JKT | G32: 45079 | I32: 4200000 | J32: 7350000 | K32: =J32-I32 -> 3150000
F33: Total Profit Domestik | K33: =SUM(K31:K32) -> 5650000
F35: Total Export Import & Domestik | K35: =K20+K27+K33 -> 46703575
F36: Target Marketing | K36: 36000000
F38: Total Komisi 12,5% | K38: =K35*12.5/100 -> 5837946.9

Sheet MSR JULI 2023
A1: MSR JULY 2023
A2: Marketing : IKA
A3: PERIODE JULI 01-31 JULY 2023
A4: IMPORT
A5: NO | B5: REFF NO | C5: DESCRIPTION | D5: CUSTOMER | E5: NO. B/L | F5: ORIGIN | G5: ETA | H5: PAYMENT DATE | I5: BUYING | J5: SELLING | K5: PROFIT
A7: 1 | B7: 008/IMP/VI/23 | C7: IMPORT CC | D7: PT. CITRA PERDANA PUTRA | E7: COAU8038801920 | F7: DALIAN | G7: 45108 | H7: 24/08/2023 -REIMBURS BLM DI BYAR | I7: 5150000 | J7: 6025000 | K7: =J7-I7 -> 875000
A8: 2 | B8: 011/IMP/VI/23 | C8: IMPORT CC | D8: PT. CITRA PERDANA PUTRA | E8: KMTCTAO6894383 | F8: QINGDAO | G8: 45109 | H8: 45162 | I8: 1650000 | J8: 2275000 | K8: =J8-I8 -> 625000
A9: 3 | B9: 009/IMP/VI/23 | C9: IMPORT OF ONLY | D9: PT. BERCA MANDIRI PERKASA | E9: SITGSHJTQ118116 | F9: SHANGHAI | G9: - | H9: 17/07/2023 | I9: 187125000 | J9: 194224100 | K9: =J9-I9 -> 7099100
A10: 4 | B10: 010/IMP/VI/23 | C10: IMPORT CC & OF | D10: PT. BERCA MANDIRI PERKASA | E10: SITGSHJTQ118120 | F10: SHANGHAI | G10: 45111 | H10: 27/07/2023 OF - 11/09/2023 CC | I10: 50750000 | J10: 58095600 | K10: =J10-I10 -> 7345600
A11: 5 | B11: 008/IMP/VII/23 | C11: IMPORT - OF & CC | D11: PT. BERCA MANDIRI PERKASA | E11: WS230700039 / CPL0113847 | F11: SHANGHAI | G11: 45138 | H11: 04/09/2023 OF | I11: 71020000 | J11: 89015480 | K11: =J11-I11 -> 17995480
A12: 6 | B12: 003/IMP/VII/23 | C12: IMPORT CC & OF | D12: PT. BERCA MANDIRI PERKASA | E12: WS230700008 / MEDUQC689674 | F12: QINGDAO | G12: 45137 | H12: 14/08/2023 OF | I12: 9450000 | J12: 12154560 | K12: =J12-I12 -> 2704560
A13: 7 | B13: 007/IMP/VII/23 | C13: IMPORT CC & OF | D13: PT. BERCA MANDIRI PERKASA | E13: WS230700028 / 025D642007 | F13: SHANGHAI | G13: 45129 | H13: 04/09/2023 OF | I13: 59000000 | J13: 93404800 | K13: =J13-I13 -> 34404800
A14: 8 | B14: 012/IMP/VI/23 | C14: IMPORT, CC & TRUCK | D14: PT. ARYASATYA MAKMUR LESTARI | E14: HCS344717JKR | F14: HO CHI MINH | G14: 45089 | H14: 45163 | I14: 1800000 | J14: 2900000 | K14: =J14-I14 -> 1100000
A15: 9 | B15: 013/IMP/VI/23 | C15: IMPORT CC & TRUCK | D15: PT. CITRA PERDANA PUTRA | E15: 2703040501 | F15: XINGANG | G15: 45117 | H15: 45198 | I15: 3630000 | J15: 4505000 | K15: =J15-I15 -> 875000
A16: 10 | B16: 001/IMP/VII/23 | C16: IMPORT CC & TRUCK | D16: PT. CITRA PERDANA PUTRA | E16: NSA-JKTG119834 | F16: NANSHA | G16: 45124 | H16: 45196 | I16: 3150000 | J16: 4700000 | K16: =J16-I16 -> 1550000
A17: 11 | B17: 003/IMP/VII/23 | C17: IMPORT CC & TRUCK | D17: PT. CITRA PERDANA PUTRA | E17: COAU8039648240 | F17: DALIAN | G17: 45137 | H17: 45209 | I17: 3250000 | J17: 4150000 | K17: =J17-I17 -> 900000
A18: 12 | B18: 002/IMP/VII/23 | C18: IMPORT CC & TRUCK | D18: PT. CITRA PERDANA PUTRA | E18: OOLU2721618793 | F18: SHEKOU | G18: 45138 | H18: 45209 | I18: 3450000 | J18: 4700000 | K18: =J18-I18 -> 1250000
F19: Total Profit Import | K19: =SUM(K7:K18) -> 76724540
A20: EXPORT
A21: NO | B21: REFF NO | C21: DESCRIPTION | D21: CUSTOMER | E21: NO. B/L | F21: DESTINASI | G21: ETD | H21: PAYMENT DATE | I21: BUYING | J21: SELLING | K21: PROFIT
A23: 13 | B23: 015/OTH/23 | C23: EXPORT CUSTOM & TRUCKING | D23: PT. DOLPHIN FOOD & BEVERAGES INDUSTRY | E23: 1KT888751 / WB854625 | F23: JKT-FIJI ISLAND | G23: 45118 | H23: 45135 | I23: 2810500 | J23: 3700000 | K23: =J23-I23 -> 889500
A24: 14 | B24: 016/OTH/23 | C24: EXPORT CC | D24: PT. BINA NIAGA MULTIUSAHA | E24: JKT300380300 | F24: JKT-FELIXSTOWE | G24: 45135 | H24: 45177 | I24: 3200000 | J24: 4650000 | K24: =J24-I24 -> 1450000
F25: Total Profit Export | K25: =SUM(K23:K24) -> 2339500
A26: LOKAL / DOMESTIK
A27: NO | B27: REFF NO | C27: DESCRIPTION | D27: CUSTOMER | E27: NO. B/L | F27: DESTINASI | G27: ETD | H27: PAYMENT DATE | I27: BUYING | J27: SELLING | K27: PROFIT
A29: 15 | B29: 005/DOM/VII/23 | C29: DOMESTIK AF | D29: PT. POLYCHEMIE ASIA PACIFIC PERMAI | E29: 938-36176361 | F29: CGK TO PADANG | G29: 45115 | H29: 45187 | I29: 3198000 | J29: 5502500 | K29: =J29-I29 -> 2304500
A30: 16 | B30: 006/DOM/VII/23 | C30: DOMESTIK AF | D30: PT. POLYCHEMIE ASIA PACIFIC PERMAI | E30: 237-00130130 | F30: CGK TO PANGKEP | G30: 45115 | H30: 45187 | I30: 4437000 | J30: 6815000 | K30: =J30-I30 -> 2378000
A31: 17 | B31: 007/DOM/VII/23 | C31: DOMESTIK | D31: PT. BERCA MANDIRI PERKASA | E31: 182/SKPB-MSD-MH/VII/23 | F31: JATAKE - CAKUNG | G31: 45048 | H31: 45180 | I31: 5500000 | J31: 6500000 | K31: =J31-I31 -> 1000000
F32: Total Profit Domestik | K32: =SUM(K29:K31) -> 5682500
F34: Total Export Import & Domestik | K34: =K19+K25+K32 -> 84746540
F35: Target Marketing | K35: 36000000
F37: Total Komisi 12,5% | K37: =K34*12.5/100 -> 10593318

Sheet MSR AGUSTUS 2023
A1: MSR AGUSTUS 2023
A2: Marketing : IKA
A3: PERIODE 01-31 AGUSTUS 2023
A4: IMPORT
A5: NO | B5: REFF NO | C5: DESCRIPTION | D5: CUSTOMER | E5: NO. B/L | F5: ORIGIN | G5: ETA | H5: PAYMENT DATE | I5: BUYING | J5: SELLING | K5: PROFIT
A7: 1 | B7: 018/IMP/VII/23 | C7: IMPORT OF & CC | D7: PT. BERCA MANDIRI PERKASA | E7: WS230700119 / JJCSHJKA389416 | F7: SHANGHAI | G7: 45147 | H7: 45180 | I7: 33750000 | J7: 42020080 | K7: =J7-I7 -> 8270080
A8: 2 | B8: 0014/IMP/VIII/23 | C8: IMPORTAF | D8: PT. AGRAPRANA JAYA EXPRESS / PT. POLYCHEMIE | E8: WS23080062 / 112-14098173 | F8: PUDONG - CGK | G8: 45151 | H8: 45152 | I8: 11565000 | J8: 21056020 | K8: =J8-I8 -> 9491020
A9: 3 | B9: 004/IMP/VII/23 | C9: IMPORT CC | D9: PT. CITRA PERDANA PUTRA | E9: MEDUDI737468 | F9: DALIAN | G9: 45153 | I9: 15820000 | J9: 18650000 | K9: =J9-I9 -> 2830000
A10: 4 | B10: 001/IMP/VIII/23 | C10: IMPORT CC | D10: PT. ALADDIN INDONESIA | E10: CENJKT23088503 | F10: QINGDAO | G10: 45157 | I10: 700000 | J10: 2300000 | K10: =J10-I10 -> 1600000
A11: 5 | B11: 009/IMP/VIII/23 | C11: IMPORT OF & CC | D11: PT. BERCA MANDIRI PERKASA | E11: WS230800054 / KMTCSHAL013520D | F11: SHANGHAI JKT | G11: 45165 | H11: 45187 | I11: 16890000 | J11: 21306140 | K11: =J11-I11 -> 4416140
A12: 6 | B12: 010/IMP/VIII/23 | C12: IMPORT OF & CC | D12: PT. BERCA MANDIRI PERKASA | E12: WS230800080 / YMLUI236318560 | F12: SHANGHAI TO BATAM | G12: 45165 | H12: 45187 | I12: 29200000 | J12: 37573800 | K12: =J12-I12 -> 8373800
A13: 7 | B13: 006/IMP/VIII/23 | C13: IMPORT OF ONLY | D13: PT. TRUELOGS GEO ENERGI | E13: S3PL/23-24/00/ FBLDJKT0823/00724 | F13: NEW DELHI | G13: 45167 | H13: 45170 | I13: 9029800 | J13: 14500000 | K13: =J13-I13 -> 5470200
A14: 8 | B14: 004/IMP/VIII/23 | C14: IMPORT OF & CC | D14: PT. BERCA MANDIRI PERKASA | E14: SITGSHJTQ116945 | F14: SHANGHAI - JKT | G14: 45167 | H14: 45187 | I14: 214400000 | J14: 256426000 | K14: =J14-I14 -> 42026000
A15: 9 | B15: 016/IMP/VIII/23 | C15: IMPORT OF & CC | D15: PT. BERCA MANDIRI PERKASA | E15: S00245344 /MEDUQK124541 | F15: NINGBO JKT | G15: 45169 | H15: 45187 | I15: 5975000 | J15: 10744435 | K15: =J15-I15 -> 4769435
A16: 10 | B16: 002/IMP/VIII/23 | C16: IMPORT CC | D16: PT. CITRA PERDANA PUTRA | E16: H2300749423 | F16: QINGDAO JKT | G16: 45169 | I16: 3550000 | J16: 4700000 | K16: =J16-I16 -> 1150000
A17: 11 | B17: 003/IMP/VIII/23 | C17: IMPORT CC | D17: PT. CITRA PERDANA PUTRA | E17: 273187656 | F17: XINGGANG JKT | G17: 45169 | I17: 2825000 | J17: 3362500 | K17: =J17-I17 -> 537500
A18: 12 | B18: 017/IMP/VIII/23 | C18: IMPORT OF & CC | D18: PT. BERCA MANDIRI PERKASA | E18: WS230800089 / 177IETETS03757UWS | F18: SHANGHAI TO JKT | G18: 45173 | H18: 45187 | I18: 35700000 | J18: 54139600 | K18: =J18-I18 -> 18439600
A19: 13 | B19: 018/IMP/VIII/23 | C19: IMPORT OF & CC | D19: PT. BERCA MANDIRI PERKASA | E19: WS230800091 / 177IETETS03756UWS | F19: SHANGHAI TO JKT | G19: 45173 | H19: 45187 | I19: 35700000 | J19: 54139600 | K19: =J19-I19 -> 18439600
F20: Total Profit Import | K20: =SUM(K7:K19) -> 125813375
F22: Total Export Import & Domestik | K22: =K20 -> 125813375
F23: Target Marketing | K23: 100000000
F25: Total Komisi 15% | K25: =K22*15/100 -> 18872006

Sheet MSR SEPTEMBER 2023
A1: MSR SEPTEMBER 2023
A2: Marketing : IKA
A3: PERIODE 01-30 SEPTEMBER 2023
A4: IMPORT
A5: NO | B5: REFF NO | C5: DESCRIPTION | D5: CUSTOMER | E5: NO. B/L | F5: ORIGIN | G5: ETA | H5: TGL PAYMENT | I5: BUYING | J5: SELLING | K5: PROFIT
A7: 1 | B7: 005/IMP/VIII/23 | C7: IMPORT - OF & CC | D7: PT. BERCA MANDIRI PERKASA | E7: GTD0798916 | F7: LAEM CHABANG - JKT | G7: 45174 | H7: 20/11/23 | I7: 8200000 | J7: 11700000 | K7: =J7-I7 -> 3500000
A8: 2 | B8: 007/IMP/VIII/23 | C8: IMPORT, CC & TRUCK | D8: PT. ARYASATYA MAKMUR LESTARI | E8: MCLMAA2301259 | F8: CHENNAI, INDIA | G8: 45175 | H8: 45210 | I8: 1800000 | J8: 3000000 | K8: =J8-I8 -> 1200000
A9: 3 | B9: 006/IMP/VIII/23 | C9: IMPORT CC | D9: PT. CITRA PERDANA PUTRA | E9: 273187646 | F9: XINGGANG JKT | G9: 45176 | H9: 24/10/2023 | I9: 3550000 | J9: 4750000 | K9: =J9-I9 -> 1200000
A10: 4 | B10: 10/IMP/IX/23 | C10: IMPORT CC & TRUCK | D10: PT. BERCA MANDIRI PERKASA | E10: GUA23090001 / 784-02585730 | F10: GUANGZHOU - CGK | G10: 45181 | H10: 20/11/23 | I10: 850000 | J10: 1637600 | K10: =J10-I10 -> 787600
